2025-07-14 14:44:41,715] ERROR in tree: Ignoring exception in command 'avatar'
Traceback (most recent call last):
  File "d:\Bot-Chuot\src\commands\general\user_info.py", line 46, in avatar
    await interaction.response.send_message(embed=embed_msg)
  File "C:\Users\ADMIN\AppData\Roaming\Python\Python313\site-packages\discord\interactions.py", line 774, in send_message
    raise InteractionResponded(self._parent)
discord.errors.InteractionResponded: This interaction has already been responded to before

During handling of the above exception, another exception occurred:

Traceback (most recent call last):
  File "C:\Users\ADMIN\AppData\Roaming\Python\Python313\site-packages\discord\app_commands\commands.py", line 827, in _do_call
    return await self._callback(self.binding, interaction, **params)  # type: ignore
           ^^^^^^^^^^^^^^^^^^^^^^^^^^^^^^^^^^^^^^^^^^^^^^^^^^^^^^^^^
  File "d:\Bot-Chuot\src\commands\general\user_info.py", line 72, in avatar
    await interaction.response.send_message(
    ...<2 lines>...
    )
  File "C:\Users\ADMIN\AppData\Roaming\Python\Python313\site-packages\discord\interactions.py", line 774, in send_message
    raise InteractionResponded(self._parent)
discord.errors.InteractionResponded: This interaction has already been responded to before

The above exception was the direct cause of the following exception:

Traceback (most recent call last):
  File "C:\Users\ADMIN\AppData\Roaming\Python\Python313\site-packages\discord\app_commands\tree.py", line 1248, in _call
    await command._invoke_with_namespace(interaction, namespace)
  File "C:\Users\ADMIN\AppData\Roaming\Python\Python313\site-packages\discord\app_commands\commands.py", line 853, in _invoke_with_namespace
    return await self._do_call(interaction, transformed_values)
           ^^^^^^^^^^^^^^^^^^^^^^^^^^^^^^^^^^^^^^^^^^^^^^^^^^^^
  File "C:\Users\ADMIN\AppData\Roaming\Python\Python313\site-packages\discord\app_commands\commands.py", line 846, in _do_call
    raise CommandInvokeError(self, e) from e
discord.app_commands.errors.CommandInvokeError: Command 'avatar' raised an exception: InteractionResponded: This interaction has already been responded to before       
404 Not Found (error code: 10062): Unknown interaction
